Workbook

Sheet 00_Index
A1: Sacred Adventures — Decision Engine
A2: Layered map of the live system for AI and humans. Read top-down: each level is more exact than the last. Built 2026-10-22 at commit e22e24d. Zero-trust: 'Assumed' = comments/docs, 'Verified' = measured.
A4: Sheet | B4: Level | C4: What it holds | D4: Read it when | E4: Rows
A5: 10_System | B5: L1 System | C5: Headline facts about the whole system, computed from the deeper sheets. | D5: Start of every session; after a rebuild. | E5: —
A6: 11_Boot_Sequence | B6: L1 System | C6: Exact module activation order from index.html. | D6: Adding, removing or reordering modules. | E6: =COUNTA('11_Boot_Sequence'!A5:A2000)
A7: 12_Frame_Loop | B7: L1 System | C7: What runs inside one RAF frame, in order, with cadence and cost class. | D7: Any FPS or stutter problem. | E7: =COUNTA('12_Frame_Loop'!A5:A2000)
A8: 20_Subsystems | B8: L2 Subsystems | C8: Each subsystem: assumed role vs verified reality, size, members, findings, plan. | D8: Choosing where a change belongs. | E8: =COUNTA('20_Subsystems'!A5:A2000)
A9: 30_Modules | B9: L3 Modules | C9: Every JS file: status, assumed vs verified behaviour, and all connections. | D9: Before editing any file. | E9: =COUNTA('30_Modules'!A5:A2000)
A10: 40_Connections | B10: L4 Contracts | C10: Every edge: imports, globals, ANU events, services, assets, postMessage. | D10: Tracing what a change will touch. | E10: =COUNTA('40_Connections'!A5:A2000)
A11: 41_Globals | B11: L4 Contracts | C11: window.* names written/read by live code — the de-facto integration layer. | D11: A value changes unexpectedly. | E11: =COUNTA('41_Globals'!A5:A2000)
A12: 42_Events | B12: L4 Contracts | C12: ANU_EVENTS vocabulary: who dispatches, who subscribes. | D12: Wiring behaviour through ANU. | E12: =COUNTA('42_Events'!A5:A2000)
A13: 43_Services | B13: L4 Contracts | C13: RuntimeServices registry: registrations and consumers. | D13: Adding a cross-module dependency. | E13: =COUNTA('43_Services'!A5:A2000)
A14: 44_Limbo_Calls | B14: L4 Contracts | C14: Every message, event, service, window function and DOM id sent by live code, matched to a receiver. | D14: A call or message seems to do nothing. | E14: =COUNTA('44_Limbo_Calls'!A5:A2000)
A15: 50_Findings | B15: L5 Evidence | C15: Forensic findings: assumed vs verified, file:line evidence, fix, plan link. | D15: Prioritising work; proving a claim. | E15: =COUNTA('50_Findings'!A5:A2000)
A16: 51_Assets | B16: L5 Evidence | C16: Measured geometry and textures of every live 3D asset, boot totals, and lite variants. | D16: Any GPU memory or triangle question. | E16: =COUNTA('51_Assets'!A5:A2000)
A17: 52_Claims_vs_Verified | B17: L5 Evidence | C17: Statements in docs/comments checked against the code. | D17: Before trusting any comment or doc. | E17: =COUNTA('52_Claims_vs_Verified'!A5:A2000)
A18: 60_Plan | B18: L6 Plan | C18: Ordered optimisation plan tied to findings and files, with acceptance tests and status. | D18: Deciding the next step; updating progress. | E18: =COUNTA('60_Plan'!A5:A2000)
A19: 61_Decision_Log | B19: L6 Plan | C19: Why each choice was made, the evidence, and how it was verified. | D19: Repeating an error; revisiting a choice. | E19: =COUNTA('61_Decision_Log'!A5:A2000)
A20: 62_Review_Playbook | B20: L6 Plan | C20: Symptom → where to cut in → mechanical check → last result. | D20: A known symptom reappears. | E20: =COUNTA('62_Review_Playbook'!A5:A2000)
A21: 63_Attempts_Ledger | B21: L6 Plan | C21: What was tried, by whom, the result, and whether it must not be retried. | D21: Before trying a fix — check it has not already failed. | E21: =COUNTA('63_Attempts_Ledger'!A5:A2000)
A22: 70_Session_Log | B22: L7 Session | C22: What was done, in order, and the next step. | D22: Resuming work. | E22: =COUNTA('70_Session_Log'!A5:A2000)
A23: 90_Glossary | B23: Reference | C23: Terms used across the workbook. | D23: An unfamiliar term. | E23: =COUNTA('90_Glossary'!A5:A2000)
A25: ID scheme | B25: SUB- subsystem · MOD- file · AST- asset · EDG- edge · GLB- global · EVT- event · SVC- service · LMB- limbo call · FND- finding · CLM- claim · PLN- plan · DEC- decision · RVW- review · ATT- attempt · LOG- session.
A26: How to navigate | B26: Problem → 62_Review_Playbook (symptom) → 50_Findings (evidence) → 30_Modules (file + connections) → 40_Connections (blast radius) → 60_Plan.
A27: Update protocol | B27: Before a fix: check 63_Attempts_Ledger. After any code change: rerun tools/decision-engine/rebuild.sh, search for 'NOT FOUND', update 60_Plan, append to 63_Attempts_Ledger and 70_Session_Log.
A28: Repo rules that bind edits | B28: Scope lock (name files + reason before editing) · never obscure #pipCanvas / PiP without explicit approval · no destructive git.
A29: Not measured here | B29: Runtime FPS, GPU timings, real draw calls: no browser ran in this environment. Those cells say 'est.' or 'not profiled'.

Sheet 10_System
A1: System facts
A2: Counts and totals are formulas over the deeper sheets; inputs from code are cited
A4: Fact | B4: Value | C4: Source / formula basis
A5: Repository commit | B5: e22e24d | C5: git rev-parse --short HEAD at build
A6: Workbook built | B6: 2026-10-22 | C6: build_engine.py
A7: Live entry page | B7: index.html | C7: index.html:L431
A8: Legacy entry page | B8: index.v2.html (linked from launch.html) | C8: launch.html:L133
A9: Files tracked in 30_Modules | B9: =COUNTA('30_Modules'!$A$5:$A$111) | C9: 30_Modules
A10: Active modules | B10: =COUNTIF('30_Modules'!$E$5:$E$111,"Active") | C10: 30_Modules status
A11: Imported libraries (no lifecycle) | B11: =COUNTIF('30_Modules'!$E$5:$E$111,"Imported library (no module lifecycle)") | C11: 30_Modules status
A12: Registered, activation commented out | B12: =COUNTIF('30_Modules'!$E$5:$E$111,"Registered, activation commented out") | C12: 30_Modules status
A13: Legacy v2 build only | B13: =COUNTIF('30_Modules'!$E$5:$E$111,"Legacy v2 build only (index.v2.html)") | C13: 30_Modules status
A14: Unreferenced by any entry page | B14: =COUNTIF('30_Modules'!$E$5:$E$111,"Unreferenced by any entry page") | C14: 30_Modules status
A15: Boot triangles (desktop, measured assets) | B15: ='51_Assets'!F22 | C15: 51_Assets totals
A16: Boot texture VRAM est. (MB, per context) | B16: ='51_Assets'!J22 | C16: 51_Assets totals
A17: WebGL contexts on desktop | B17: 2 | C17: js/v2/Orchestrator.js:L1114
A18: Calls with no live receiver (limbo) | B18: =COUNTIF('44_Limbo_Calls'!$F$5:$F$205,"LIMBO*") | C18: 44_Limbo_Calls
A19: Boot triangles before PLN-01 + PLN-02 | B19: ='51_Assets'!F23 | C19: 51_Assets totals
A20: Texture VRAM before PLN-01 + PLN-02 (MB) | B20: ='51_Assets'!J24 | C20: 51_Assets totals
A21: Triangles removed by PLN-01 + PLN-02 | B21: ='51_Assets'!F23-'51_Assets'!F22 | C21: difference
A22: Live globals (window.*) | B22: =COUNTA('41_Globals'!$A$5:$A$113) | C22: 41_Globals
A23: ANU events with a live subscriber | B23: =COUNTIF('42_Events'!$F$5:$F$29,"Live round trip") | C23: 42_Events
A24: Open findings (Critical + High) | B24: =COUNTIF('50_Findings'!$B$5:$B$48,"Critical")+COUNTIF('50_Findings'!$B$5:$B$48,"High") | C24: 50_Findings
A25: Plan steps done (incl. code-done awaiting browser check) | B25: =COUNTIF('60_Plan'!$G$5:$G$25,"Done*")&" of "&COUNTA('60_Plan'!$A$5:$A$25) | C25: 60_Plan status
A26: PiP stride baseline / max | B26: 16 / 22 | C26: js/v2/constants.js:L63 · js/v2/constants.js:L73
A27: Target FPS constant | B27: 65 | C27: js/v2/constants.js:L66
A28: Main renderer DPR cap (desktop / mobile) | B28: 1.5 / 1.0 | C28: js/v2/Orchestrator.js:L130
A29: Save key (localStorage) | B29: v4.sanctuary.save | C29: js/sanctuary/SanctuaryControls.js:L21

Sheet 11_Boot_Sequence
A1: Boot sequence
A2: Activation order in index.html · evidence re-located at build · commit e22e24d
A4: Order | B4: Module name | C4: Module ID | D4: File | E4: Subsystem | F4: Suspended while fishing | G4: Evidence
A5: 1 | B5: Anu | C5: MOD-049 | D5: js/v2/AnuModule.js | E5: SUB-03 | G5: index.html:L497
A6: 2 | B6: AnuAdaptiveDpr | C6: MOD-002 | D6: js/sanctuary/AnuAdaptiveDpr.js | E6: SUB-04 | G6: index.html:L500
A7: 3 | B7: SanctuaryGround | C7: MOD-027 | D7: js/sanctuary/SanctuaryGround.js | E7: SUB-06 | G7: index.html:L503
A8: 4 | B8: SanctuaryPool | C8: MOD-035 | D8: js/sanctuary/SanctuaryPool.js | E8: SUB-06 | G8: index.html:L506
A9: 5 | B9: SanctuaryDock | C9: MOD-019 | D9: js/sanctuary/SanctuaryDock.js | E9: SUB-06 | G9: index.html:L509
A10: 6 | B10: SanctuaryFish | C10: MOD-021 | D10: js/sanctuary/SanctuaryFish.js | E10: SUB-07 | G10: index.html:L512
A11: 7 | B11: SanctuaryCircles | C11: MOD-014 | D11: js/sanctuary/SanctuaryCircles.js | E11: SUB-06 | G11: index.html:L515
A12: 8 | B12: SanctuaryAvatar | C12: MOD-011 | D12: js/sanctuary/SanctuaryAvatar.js | E12: SUB-08 | G12: index.html:L528
A13: 9 | B13: SanctuaryClickToMove | C13: MOD-015 | D13: js/sanctuary/SanctuaryClickToMove.js | E13: SUB-08 | F13: Yes | G13: index.html:L531
A14: 10 | B14: SanctuaryWaterFootsteps | C14: MOD-043 | D14: js/sanctuary/SanctuaryWaterFootsteps.js | E14: SUB-08 | G14: index.html:L534
A15: 11 | B15: SanctuaryWorldPlayerShim | C15: MOD-046 | D15: js/sanctuary/SanctuaryWorldPlayerShim.js | E15: SUB-08 | G15: index.html:L537
A16: 12 | B16: SanctuarySky | C16: MOD-037 | D16: js/sanctuary/SanctuarySky.js | E16: SUB-06 | F16: Yes | G16: index.html:L540
A17: 13 | B17: SanctuaryMutations | C17: MOD-033 | D17: js/sanctuary/SanctuaryMutations.js | E17: SUB-10 | F17: Yes | G17: index.html:L543
A18: 14 | B18: MoldGrowHill | C18: MOD-003 | D18: js/sanctuary/MoldGrowHill.js | E18: SUB-10 | F18: Yes | G18: index.html:L546
A19: 15 | B19: MoldPlantTree | C19: MOD-009 | D19: js/sanctuary/MoldPlantTree.js | E19: SUB-10 | F19: Yes | G19: index.html:L549
A20: 16 | B20: MoldPlantFlower | C20: MOD-006 | D20: js/sanctuary/MoldPlantFlower.js | E20: SUB-10 | F20: Yes | G20: index.html:L552
A21: 17 | B21: MoldPlantBush | C21: MOD-005 | D21: js/sanctuary/MoldPlantBush.js | E21: SUB-10 | F21: Yes | G21: index.html:L555
A22: 18 | B22: MoldPlantLily | C22: MOD-007 | D22: js/sanctuary/MoldPlantLily.js | E22: SUB-10 | F22: Yes | G22: index.html:L556
A23: 19 | B23: MoldPlantRock | C23: MOD-008 | D23: js/sanctuary/MoldPlantRock.js | E23: SUB-10 | F23: Yes | G23: index.html:L557
A24: 20 | B24: MoldPlaceTipi | C24: MOD-004 | D24: js/sanctuary/MoldPlaceTipi.js | E24: SUB-10 | F24: Yes | G24: index.html:L558
A25: 21 | B25: SanctuaryButterflies | C25: MOD-013 | D25: js/sanctuary/SanctuaryButterflies.js | E25: SUB-07 | F25: Yes | G25: index.html:L561
A26: 22 | B26: SanctuaryToolPalette | C26: MOD-040 | D26: js/sanctuary/SanctuaryToolPalette.js | E26: SUB-10 | F26: Yes | G26: index.html:L564
A27: 23 | B27: SanctuaryMapGeneratorUi | C27: MOD-032 | D27: js/sanctuary/SanctuaryMapGeneratorUi.js | E27: SUB-10 | F27: Yes | G27: index.html:L565
... A29: 25 | B29: SanctuaryZoom | C29: MOD-048 | D29: js/sanctuary/SanctuaryZoom.js | E29: SUB-08 | F29: Yes | G29: index.html:L571
A30: 26 | B30: PanelsPIP | C30: MOD-064 | D30: js/v2/UIModule.js | E30: SUB-05 | G30: index.html:L574
A31: 27 | B31: SanctuaryVillagePad | C31: MOD-042 | D31: js/sanctuary/SanctuaryVillagePad.js | E31: SUB-10 | F31: Yes | G31: index.html:L577
A32: 28 | B32: SanctuaryTipis | C32: MOD-039 | D32: js/sanctuary/SanctuaryTipis.js | E32: SUB-10 | F32: Yes | G32: index.html:L580
A33: 29 | B33: SanctuaryTipiNpcs | C33: MOD-038 | D33: js/sanctuary/SanctuaryTipiNpcs.js | E33: SUB-09 | F33: Yes | G33: index.html:L583
A34: 30 | B34: SanctuaryBraziers | C34: MOD-012 | D34: js/sanctuary/SanctuaryBraziers.js | E34: SUB-10 | F34: Yes | G34: index.html:L586
A35: 31 | B35: SanctuaryFishJumps | C35: MOD-022 | D35: js/sanctuary/SanctuaryFishJumps.js | E35: SUB-07 | G35: index.html:L589
A36: 32 | B36: SanctuaryControls | C36: MOD-016 | D36: js/sanctuary/SanctuaryControls.js | E36: SUB-12 | G36: index.html:L592
A37: 33 | B37: SanctuaryDayNight | C37: MOD-018 | D37: js/sanctuary/SanctuaryDayNight.js | E37: SUB-06 | G37: index.html:L595
A38: 34 | B38: SanctuaryCursor | C38: MOD-017 | D38: js/sanctuary/SanctuaryCursor.js | E38: SUB-08 | F38: Yes | G38: index.html:L598
A39: 35 | B39: SanctuaryAmbient | C39: MOD-010 | D39: js/sanctuary/SanctuaryAmbient.js | E39: SUB-06 | F39: Yes | G39: index.html:L601
A40: 36 | B40: SanctuaryInventory | C40: MOD-029 | D40: js/sanctuary/SanctuaryInventory.js | E40: SUB-12 | F40: Yes | G40: index.html:L604
A41: 37 | B41: SanctuaryWeather | C41: MOD-044 | D41: js/sanctuary/SanctuaryWeather.js | E41: SUB-06 | F41: Yes | G41: index.html:L607
A42: 38 | B42: SanctuaryFishing | C42: MOD-023 | D42: js/sanctuary/SanctuaryFishing.js | E42: SUB-11 | G42: index.html:L611
...

Sheet 12_Frame_Loop
A1: Frame loop
A2: SacredOrchestrator._loop — order of work in one frame
A4: Step | B4: Work | C4: Cadence | D4: Evidence | E4: Cost class | F4: Findings
A5: 1 | B5: FPS EMA smoothing | C5: Every frame | D5: js/v2/Orchestrator.js:L666 | E5: CPU, trivial
A6: 2 | B6: AnuNatureAwareness.tick() | C6: Every frame | D6: js/v2/Orchestrator.js:L698 | E6: CPU, trivial
A7: 3 | B7: 43 module update() calls in activation order (27 skipped while fishing) | C7: Every frame | D7: js/v2/Orchestrator.js:L702 | E7: CPU; see 30_Modules hazards | F7: FND-17
A8: 4 | B8: Benchmark tick | C8: Every frame while a bench runs | D8: js/v2/Orchestrator.js:L721 | E8: CPU, trivial | F8: FND-14
A9: 5 | B9: Stress level → shadow autoUpdate / sampling | C9: Every frame | D9: js/v2/Orchestrator.js:L737 | E9: GPU: shadow pass every frame when OPTIMAL | F9: FND-16
A10: 6 | B10: PiP bypass hysteresis (CRITICAL → off, OPTIMAL → on) | C10: Every frame | D10: js/v2/Orchestrator.js:L770 | E10: Decision only | F10: FND-08
A11: 7 | B11: Main render | C11: Every frame | D11: js/v2/Orchestrator.js:L773 | E11: GPU: ~4.0M boot triangles | F11: FND-01, FND-02, FND-15
A12: 8 | B12: PiP render (2nd context): FPV map stride 16 · Village View every frame · fishing every 2nd | C12: Variable | D12: js/v2/Orchestrator.js:L1392 | E12: GPU: full scene again + MSAA; CPU: scene traversal per pass | F12: FND-04, FND-05, FND-06
A13: 9 | B13: HUD values (+ ANU audit and governance at 2 Hz) | C13: Every 20 frames | D13: js/v2/Orchestrator.js:L783 | E13: CPU + DOM writes
A14: 10 | B14: recordFrameDuration + tickAdaptiveRenderPolicy | C14: Every frame | D14: js/v2/Orchestrator.js:L799 | E14: Feeds JS-only time to governors | F14: FND-07
A15: 11 | B15: Stress ledger sample | C15: Every 45 frames | D15: js/v2/Orchestrator.js:L808 | E15: CPU, small
A16: 12 | B16: Scene inventory walk | C16: Every 120 frames | D16: js/v2/Orchestrator.js:L819 | E16: CPU spike: traverse + getWorldPosition per object | F16: FND-09
A17: 13 | B17: ANU alert evaluation (inside AnuModule.update) | C17: Every 240 frames | D17: js/v2/AnuModule.js:L536 | E17: CPU, small

Sheet 20_Subsystems
A1: Subsystems
A2: Counts are live formulas over 30_Modules
A4: Subsystem ID | B4: Subsystem | C4: Assumed role (docs/comments) | D4: Verified reality (mechanical) | E4: Files (count) | F4: Active modules | G4: Lines of code | H4: Module IDs | I4: Findings | J4: Plan steps
A5: SUB-01 | B5: Boot & entry | C5: Loads the page, import map, loading modal, registers and activates modules in a fixed order. | D5: index.html is the only live entry; index.v2.html is an older v2 build reachable from launch.html. | E5: =COUNTIF('30_Modules'!$C$5:$C$111,A5) | F5: =COUNTIFS('30_Modules'!$C$5:$C$111,A5,'30_Modules'!$E$5:$E$111,"Active") | G5: =SUMIF('30_Modules'!$C$5:$C$111,A5,'30_Modules'!$Y$5:$Y$111) | H5: MOD-001 | I5: FND-13, FND-19 | J5: PLN-10, PLN-15
A6: SUB-02 | B6: Engine shell | C6: SacredOrchestrator owns renderer, scene, camera, RAF loop, module registry, HUD. | D6: One RAF loop calls 43 active modules in activation order, then renders main + PiP. | E6: =COUNTIF('30_Modules'!$C$5:$C$111,A6) | F6: =COUNTIFS('30_Modules'!$C$5:$C$111,A6,'30_Modules'!$E$5:$E$111,"Active") | G6: =SUMIF('30_Modules'!$C$5:$C$111,A6,'30_Modules'!$Y$5:$Y$111) | H6: MOD-059, MOD-060, MOD-061 | I6: FND-11, FND-14, FND-16 | J6: PLN-11, PLN-12, PLN-13
A7: SUB-03 | B7: ANU governance & telemetry | C7: Self-observing layer: audit, governance checks, sensorium, error/stress ledger, event bus, services. | D7: Mostly read-on-demand diagnostics. InteractionBus has 0 live subscribers; inventory walk runs every 120 frames with no live reader. | E7: =COUNTIF('30_Modules'!$C$5:$C$111,A7) | F7: =COUNTIFS('30_Modules'!$C$5:$C$111,A7,'30_Modules'!$E$5:$E$111,"Active") | G7: =SUMIF('30_Modules'!$C$5:$C$111,A7,'30_Modules'!$Y$5:$Y$111) | H7: MOD-049, MOD-087, MOD-088, MOD-089, MOD-091, MOD-093, MOD-097, MOD-098, MOD-099, MOD-100, MOD-101, MOD-102 | I7: FND-09, FND-10, FND-12 | J7: PLN-08, PLN-09, PLN-12
A8: SUB-04 | B8: Render governance | C8: Adaptive DPR, PiP stride, shadow sampling driven by frame budget. | D8: Three controllers act on the same lever (PiP stride) with different thresholds; all read JS-only frame time. | E8: =COUNTIF('30_Modules'!$C$5:$C$111,A8) | F8: =COUNTIFS('30_Modules'!$C$5:$C$111,A8,'30_Modules'!$E$5:$E$111,"Active") | G8: =SUMIF('30_Modules'!$C$5:$C$111,A8,'30_Modules'!$Y$5:$Y$111) | H8: MOD-002, MOD-086, MOD-092, MOD-095, MOD-096 | I8: FND-07, FND-08 | J8: PLN-07
A9: SUB-05 | B9: PiP minimap & compass | C9: Picture-in-picture map / FPV view with compass dial. | D9: Second WebGL context on desktop; full scene re-render; every frame in Village View. | E9: =COUNTIF('30_Modules'!$C$5:$C$111,A9) | F9: =COUNTIFS('30_Modules'!$C$5:$C$111,A9,'30_Modules'!$E$5:$E$111,"Active") | G9: =SUMIF('30_Modules'!$C$5:$C$111,A9,'30_Modules'!$Y$5:$Y$111) | H9: MOD-064, MOD-094, MOD-106 | I9: FND-04, FND-05, FND-06, FND-21, FND-22, FND-25, FND-26, FND-31, FND-44 | J9: PLN-05, PLN-06, PLN-16, PLN-18, PLN-19
A10: SUB-06 | B10: World environment | C10: Ground, sky, day/night, weather, ambient audio, pool, dock, circles, pond flora. | D10: Pool and ground are procedural; pond flora is instanced (tree 18, bush 24, reeds 14). | E10: =COUNTIF('30_Modules'!$C$5:$C$111,A10) | F10: =COUNTIFS('30_Modules'!$C$5:$C$111,A10,'30_Modules'!$E$5:$E$111,"Active") | G10: =SUMIF('30_Modules'!$C$5:$C$111,A10,'30_Modules'!$Y$5:$Y$111) | H10: MOD-010, MOD-014, MOD-018, MOD-019, MOD-027, MOD-028, MOD-034, MOD-035, MOD-036, MOD-037, MOD-044 | I10: FND-35, FND-36, FND-37, FND-38, FND-39, FND-40, FND-43 | J10: PLN-21
A11: SUB-07 | B11: Fauna | C11: Fish, fish jumps, frogs, butterflies, dragonfly, nature awareness. | D11: 18 trout at 23,466 tris each as separate meshes; small fish instanced (32). | E11: =COUNTIF('30_Modules'!$C$5:$C$111,A11) | F11: =COUNTIFS('30_Modules'!$C$5:$C$111,A11,'30_Modules'!$E$5:$E$111,"Active") | G11: =SUMIF('30_Modules'!$C$5:$C$111,A11,'30_Modules'!$Y$5:$Y$111) | H11: MOD-013, MOD-020, MOD-021, MOD-022, MOD-026, MOD-090 | I11: FND-15, FND-30, FND-33, FND-34, FND-42 | J11: PLN-04, PLN-16, PLN-21
A12: SUB-08 | B12: Player | C12: Avatar, click-to-move, keyboard look, zoom, cursor, footsteps, WorldPlayer shim. | D12: Loads Avatar-New.glb (246k tris, 2×4096² maps) by default; Avatar3 only with ?avatar=old. | E12: =COUNTIF('30_Modules'!$C$5:$C$111,A12) | F12: =COUNTIFS('30_Modules'!$C$5:$C$111,A12,'30_Modules'!$E$5:$E$111,"Active") | G12: =SUMIF('30_Modules'!$C$5:$C$111,A12,'30_Modules'!$Y$5:$Y$111) | H12: MOD-011, MOD-015, MOD-017, MOD-031, MOD-041, MOD-043, MOD-046, MOD-048 | I12: FND-17, FND-29 | J12: PLN-14, PLN-20
A13: SUB-09 | B13: Population (NPCs) | C13: Seated NPCs at tipis: Yellow Butterfly, BHG, REG. | D13: Ambient only; REG is 1.94M tris on desktop and skipped on mobile. | E13: =COUNTIF('30_Modules'!$C$5:$C$111,A13) | F13: =COUNTIFS('30_Modules'!$C$5:$C$111,A13,'30_Modules'!$E$5:$E$111,"Active") | G13: =SUMIF('30_Modules'!$C$5:$C$111,A13,'30_Modules'!$Y$5:$Y$111) | H13: MOD-038, MOD-058 | I13: FND-01 | J13: PLN-01
A14: SUB-10 | B14: Structures & village building | C14: Tipis, braziers, village pad, mold tools, tool palette, building panel, map generator. | D14: Mold tools place flora/hills/rocks/tipis; building panel is list-only; 3 tipi clones of a 246k-tri model. | E14: =COUNTIF('30_Modules'!$C$5:$C$111,A14) | F14: =COUNTIFS('30_Modules'!$C$5:$C$111,A14,'30_Modules'!$E$5:$E$111,"Active") | G14: =SUMIF('30_Modules'!$C$5:$C$111,A14,'30_Modules'!$Y$5:$Y$111) | H14: MOD-003, MOD-004, MOD-005, MOD-006, MOD-007, MOD-008, MOD-009, MOD-012, MOD-032, MOD-033, MOD-039, MOD-040, MOD-042, MOD-051, MOD-062, MOD-084 | I14: FND-02, FND-24 | J14: PLN-02, PLN-18
A15: SUB-11 | B15: Fishing | C15: Cast, bite turns, reel, catch, gauge, PiP gauge close-up. | D15: Largest module (2,991 lines, 981-line update). Transmission material on the gauge adds a pass while fishing. | E15: =COUNTIF('30_Modules'!$C$5:$C$111,A15) | F15: =COUNTIFS('30_Modules'!$C$5:$C$111,A15,'30_Modules'!$E$5:$E$111,"Active") | G15: =SUMIF('30_Modules'!$C$5:$C$111,A15,'30_Modules'!$Y$5:$Y$111) | H15: MOD-023 | I15: FND-18, FND-28, FND-32, FND-41 | J15: PLN-14, PLN-16, PLN-21
A16: SUB-12 | B16: Items & save | C16: Harvest inventory and SAVE/RESET of world mutations. | D16: localStorage key v4.sanctuary.save; spec key sacredAdventures_saveState not implemented. | E16: =COUNTIF('30_Modules'!$C$5:$C$111,A16) | F16: =COUNTIFS('30_Modules'!$C$5:$C$111,A16,'30_Modules'!$E$5:$E$111,"Active") | G16: =SUMIF('30_Modules'!$C$5:$C$111,A16,'30_Modules'!$Y$5:$Y$111) | H16: MOD-016, MOD-029
A17: SUB-13 | B17: UI shell & journal | C17: Panel and journal iframes, welcome guide, controls bar, HUD. | D17: postMessage bridge; HUD runs audit + governance at 2 Hz. | E17: =COUNTIF('30_Modules'!$C$5:$C$111,A17) | F17: =COUNTIFS('30_Modules'!$C$5:$C$111,A17,'30_Modules'!$E$5:$E$111,"Active") | G17: =SUMIF('30_Modules'!$C$5:$C$111,A17,'30_Modules'!$Y$5:$Y$111) | H17: MOD-030, MOD-045 | I17: FND-23 | J17: PLN-17
A18: SUB-14 | B18: Asset pipeline | C18: Draco loader, mobile GLB swap, compression scripts. | D18: Mobile swap set does not include the tipi URL the live game loads. | E18: =COUNTIF('30_Modules'!$C$5:$C$111,A18) | F18: =COUNTIFS('30_Modules'!$C$5:$C$111,A18,'30_Modules'!$E$5:$E$111,"Active") | G18: =SUMIF('30_Modules'!$C$5:$C$111,A18,'30_Modules'!$Y$5:$Y$111) | H18: MOD-104 | I18: FND-03, FND-20 | J18: PLN-03, PLN-14
A19: SUB-15 | B19: Shared config & helpers | C19: constants, maps registry, terrain/platform helpers, compass math. | D19: constants.js is imported by most modules; v2 helper files are imported for single functions. | E19: =COUNTIF('30_Modules'!$C$5:$C$111,A19) | F19: =COUNTIFS('30_Modules'!$C$5:$C$111,A19,'30_Modules'!$E$5:$E$111,"Active") | G19: =SUMIF('30_Modules'!$C$5:$C$111,A19,'30_Modules'!$Y$5:$Y$111) | H19: MOD-057, MOD-074, MOD-080, MOD-082, MOD-083, MOD-103 | I19: FND-27 | J19: PLN-18
A20: SUB-16 | B20: Legacy / unused code | C20: v2 world modules and sanctuary leftovers. | D20: 20 files only reachable from index.v2.html; 8 files reachable from no entry page. | E20: =COUNTIF('30_Modules'!$C$5:$C$111,A20) | F20: =COUNTIFS('30_Modules'!$C$5:$C$111,A20,'30_Modules'!$E$5:$E$111,"Active") | G20: =SUMIF('30_Modules'!$C$5:$C$111,A20,'30_Modules'!$Y$5:$Y$111) | H20: MOD-024, MOD-025, MOD-047, MOD-050, MOD-052, MOD-053, MOD-054, MOD-055, MOD-056, MOD-063, MOD-065, MOD-066, MOD-067, MOD-068, MOD-069, MOD-070, MOD-071, MOD-072, MOD-073, MOD-075, MOD-076, MOD-077, MOD-078, MOD-079, MOD-081, MOD-085, MOD-105, MOD-107

Sheet 30_Modules
A1: Modules
A2: 107 files under js/sanctuary, js/v2, js/v2/anu + BuildBadge · generated by extract.py
A4: Module ID | B4: File | C4: Subsystem ID | D4: Subsystem | E4: Status (verified) | F4: Activation order | G4: Module name | H4: ANU domain (claimed) | I4: Assumed purpose (header comment — treat as stale) | J4: Verified behaviour (mechanical) | K4: Imports (MOD IDs) | L4: Imported by (MOD IDs) | M4: Globals written | N4: Globals read | O4: ANU events dispatched | P4: ANU events subscribed | Q4: Runtime services | R4: postMessage / DOM events sent | S4: Assets referenced | T4: Suspended while fishing | U4: Also in v2 build | V4: Commits touching file | W4: Last commit | X4: Findings | Y4: Lines
A5: MOD-001 | B5: js/BuildBadge.js | C5: SUB-01 | D5: Boot & entry | E5: Imported library (no module lifecycle) | I5: BuildBadge — fixed bottom-left commit/sync indicator. Reads build-info.json (written by scripts/build-info.mjs via the post-commit hook) and renders a high-contrast pill showing the last commit subject, timestamp (relative + absolute), branch, SW cache version, and a DIRTY flag if the working tree has uncommitted changes. Purpose: every AI agent + the user can see at a glance which commit the current page actually reflects, so "I committed X" claims can be verified against on-screen truth. Placed bottom-left, high z-index, always on top of the main canvas. | J5: 179 lines, 7.4 KB. No update(). | V5: 5 | W5: 2026-05-29 feat(pipeline): build-signature badge — show which AI's build is live | Y5: 179
A6: MOD-002 | B6: js/sanctuary/AnuAdaptiveDpr.js | C6: SUB-04 | D6: Render governance | E6: Active | F6: 2 | G6: AnuAdaptiveDpr | I6: AnuAdaptiveDpr — Anu's omnipresent FPS guardian. Per the user's spec: "ANU/World/Animals = controlled by an omnipresent AI that monitors everything, including current FPS. This game must have threshold for 120fps at super high resolutions." What this does: • Watches `FrameBudget.avgMs` every N frames (Anu's own sensor). • If the rolling average drops below a target wall (default 120 FPS → 8.33 ms), Anu scales the renderer's pixel ratio DOWN one step. • If the rolling average comfortably exceeds the target with hysteresis, Anu scales DPR UP one step (capped at the user's device DPR). Why DPR in | J6: 285 lines, 11.5 KB. update() at L225 (50 lines). | K6: MOD-092, MOD-093, MOD-096, MOD-098, MOD-100 | N6: AnuUniverse; devicePixelRatio; innerHeight; innerWidth | O6: RENDERING_DPR_CHANGE | V6: 5 | W6: 2026-06-01 fix(mobile): stop iOS OOM crash ("Can't open this page") — cap texture memory | X6: FND-08 | Y6: 285
A7: MOD-003 | B7: js/sanctuary/MoldGrowHill.js | C7: SUB-10 | D7: Structures & village building | E7: Active | F7: 14 | G7: MoldGrowHill | I7: Sacred Adventures — sanctuary part 10 of N: MOLD TOOL · GROW HILL. First real handler against the `SanctuaryMutations` registry. When a kid clicks the ground in top-down mode, the input layer publishes a `grow_hill` mutation; THIS module materialises the mesh. Design (Anu's brief — "grow the beautiful hills that will surround our pool and sacred valley so kids can have their digital sanctuary for free"): • Each hill is a low-poly dome (half-sphere with smoothed Z-axis flattening + meadow-coloured material) anchored to the click point on the heightfield. • Radius + height are mild defaults that | J7: 130 lines, 4.8 KB. update() at L121 (0 lines). | K7: MOD-027, MOD-098 | N7: SanctuaryMutations | T7: Yes | V7: 1 | W7: 2026-05-19 feat(full-session): fishing overhaul, FPS fix, dock elevation, clean world, sanctuary v2 | Y7: 130
A8: MOD-004 | B8: js/sanctuary/MoldPlaceTipi.js | C8: SUB-10 | D8: Structures & village building | E8: Active | F8: 20 | G8: MoldPlaceTipi | I8: Sacred Adventures — sanctuary mold tool: PLACE TIPI. The first **building** tool. Lets kids drop a small procedural tipi on the ground in top-down mode. Each placed tipi is: • A cone of canvas (taupe-white) covering 12 lashed poles • A small smoke-hole opening at the top (just a tiny dark disc) • A doorway "flap" on the south side (a darker tall rectangle) • Anu STRUCTURES domain, anuKind = `mold_placed_tipi` • Serialised through the registry → restored on reload Geometry per tipi (~280 tris): cone (24-seg) + 12 lashed poles (lightweight cylinders) + doorway plane. Sizing: 3.2 m tall, 1.6 m ba | J8: 156 lines, 5.0 KB. update() at L152 (0 lines). | K8: MOD-027, MOD-098 | N8: SanctuaryMutations | T8: Yes | V8: 1 | W8: 2026-05-19 feat(full-session): fishing overhaul, FPS fix, dock elevation, clean world, sanctuary v2 | Y8: 156
A9: MOD-005 | B9: js/sanctuary/MoldPlantBush.js | C9: SUB-10 | D9: Structures & village building | E9: Active | F9: 17 | G9: MoldPlantBush | I9: Mold tool — PLANT BUSH. Each kid-placed bush is a small clump of 3-5 overlapping low-poly spheres painted leafy green with slight per-lump hue variation. Optional berry dots randomly added so some bushes carry colour. ~80 tris/bush. | J9: 142 lines, 4.3 KB. update() at L138 (0 lines). | K9: MOD-027, MOD-098 | N9: SanctuaryMutations | T9: Yes | V9: 1 | W9: 2026-05-19 feat(full-session): fishing overhaul, FPS fix, dock elevation, clean world, sanctuary v2 | Y9: 142
A10: MOD-006 | B10: js/sanctuary/MoldPlantFlower.js | C10: SUB-10 | D10: Structures & village building | E10: Active | F10: 16 | G10: MoldPlantFlower | I10: Sacred Adventures — sanctuary mold tool: PLANT FLOWER. Registers a `plant_flower` handler. Each click drops a small flower cluster (3-5 flowers in a single random colour) at the click point — same shape as the SanctuaryFlora baseline clusters but with the kid's agency stamped on it. Geometry per cluster (~50 tris). Mutation registry serialises the (x, z, colourHex) tuple so SAVE → reload reproduces the exact same colour. | J10: 120 lines, 4.0 KB. update() at L116 (0 lines). | K10: MOD-027, MOD-098 | N10: SanctuaryMutations | T10: Yes | V10: 1 | W10: 2026-05-19 feat(full-session): fishing overhaul, FPS fix, dock elevation, clean world, sanctuary v2 | Y10: 120
A11: MOD-007 | B11: js/sanctuary/MoldPlantLily.js | C11: SUB-10 | D11: Structures & village building | E11: Active | F11: 18 | G11: MoldPlantLily | H11: ENVIRONMENT | I11: Mold tool — PLANT LILY. Drops one lily pad (with a small chance of a gold flower) on the pool surface at the click point. If the click is OUTSIDE the pool radius, the mutation is rejected silently (the pad needs water to float on). Anu domain: ENVIRONMENT (decorative water-surface decoration, same as the baseline lily pads in SanctuaryPool). | J11: 135 lines, 4.1 KB. update() at L131 (0 lines). | K11: MOD-027, MOD-098 | N11: SanctuaryMutations; __sanctuaryWaterY; sanctuaryPulse | T11: Yes | V11: 1 | W11: 2026-05-19 feat(full-session): fishing overhaul, FPS fix, dock elevation, clean world, sanctuary v2 | Y11: 135
A12: MOD-008 | B12: js/sanctuary/MoldPlantRock.js | C12: SUB-10 | D12: Structures & village building | E12: Active | F12: 19 | G12: MoldPlantRock | I12: Mold tool — PLANT ROCK. Drops a small cluster of stones at the click point — 2-4 low-poly icosahedra in slate-grey tones, varied scale + yaw so each pile reads unique. ~40 tris per pile. | J12: 92 lines, 2.8 KB. update() at L88 (0 lines). | K12: MOD-027, MOD-098 | N12: SanctuaryMutations | T12: Yes | V12: 1 | W12: 2026-05-19 feat(full-session): fishing overhaul, FPS fix, dock elevation, clean world, sanctuary v2 | Y12: 92
A13: MOD-009 | B13: js/sanctuary/MoldPlantTree.js | C13: SUB-10 | D13: Structures & village building | E13: Active | F13: 15 | G13: MoldPlantTree | I13: Sacred Adventures — sanctuary mold tool: PLANT TREE. Registers a `plant_tree` handler against the SanctuaryMutations registry. When a kid clicks the ground in top-down mode with the plant_tree tool armed, a low-poly conifer drops in there. Anu domain on the spawned mesh: FLORA. Each tree is INTERACTABLE with verb `harvest` so Anu's vocabulary (which already names harvest as a verb) finally has something to act on. Geometry per tree (~120 tris): • Trunk — short tapered cylinder (8 segments). • Crown — three stacked cones with decreasing radius, slight random Y-jitter per cone so the silhouette | J13: 129 lines, 4.3 KB. update() at L125 (0 lines). | K13: MOD-027, MOD-098 | N13: SanctuaryMutations | T13: Yes | V13: 1 | W13: 2026-05-19 feat(full-session): fishing overhaul, FPS fix, dock elevation, clean world, sanctuary v2 | Y13: 129
A14: MOD-010 | B14: js/sanctuary/SanctuaryAmbient.js | C14: SUB-06 | D14: World environment | E14: Active | F14: 35 | G14: SanctuaryAmbient | H14: ENVIRONMENT | I14: Sacred Adventures — sanctuary part 27 of N: AMBIENT SOUND. Anu domain: ENVIRONMENT (the atmosphere bodies obey, audible side). Procedural ambient — entirely Web Audio, no .mp3 files. Three layers crossfade in once the AudioContext unlocks (browsers gate WebAudio behind user interaction; we wait for first click/keypress + then resume the context): 1. WIND — filtered pink noise modulated by a slow LFO. The "valley breeze" undercurrent. 2. WATER LAPPING — band-pass filtered white noise + low LFO, pulses the lapping rhythm. Volume scales with proximity to the pool (within 18 m = full). 3. BIRDSONG | J14: 254 lines, 8.5 KB. update() at L219 (12 lines). Writes 1 globals. | K14: MOD-098 | M14: __sanctuaryMuted | N14: AudioContext; __sanctuaryAvatar; addEventListener; removeEventListener; webkitAudioContext | T14: Yes | V14: 2 | W14: 2026-05-29 feat(sanctuary): center-screen responsive welcome guide, organic shore, and mossy boulders | Y14: 254
A15: MOD-011 | B15: js/sanctuary/SanctuaryAvatar.js | C15: SUB-08 | D15: Player | E15: Active | F15: 8 | G15: SanctuaryAvatar | H15: PLAYER | I15: Sacred Adventures — sanctuary part 7 of N: AVATAR. Loads `Assets/Avatar3.glb` (Draco-compressed + decimated to ~205 k tris in the May-17 simplify pass) and plants it on the sanctuary ground. Anu domain: PLAYER (the witness body). Anti-transparency treatment per user spec ("try best not to allow it to have any transparencies across its entire mesh and fill in any gaps in it with skin color filler"): 1. Every material on the rig is forced opaque: transparent = false opacity = 1.0 alphaTest = 0 depthWrite = true This kills the most common Tripo-GLB face-transparency artifact where alpha-test frag | J15: 729 lines, 30.4 KB. update() at L558 (147 lines). Per-frame hazards: alloc_three×4, matrix_update×4. Writes 2 globals. | K15: MOD-027, MOD-041, MOD-098, MOD-103, MOD-104 | M15: __sanctuaryAvatar; __sanctuaryPlayerYaw | N15: __sanctuaryDockSurface; __sanctuaryFishingActive; __sanctuaryWaterY; localStorage; location | S15: Assets/Avatar3.glb; Assets/npc/Avatar-New.glb | V15: 17 | W15: 2026-05-30 feat(fishing): two-handed hand-line to left hand + calm the rod motion | X15: FND-17, FND-29 | Y15: 729
A16: MOD-012 | B16: js/sanctuary/SanctuaryBraziers.js | C16: SUB-10 | D16: Structures & village building | E16: Active | F16: 30 | G16: SanctuaryBraziers | H16: STRUCTURES | I16: Sacred Adventures — sanctuary part 30 of N: TIPI BRAZIERS. Anu domain: STRUCTURES (the stone bowl) + ENVIRONMENT (fire + smoke). One brazier sits in front of each tipi. **Perf rewrite (May-18 2026):** • Smoke is now ONE `THREE.Points` cloud per brazier instead of 28 individual sprites. Drops 28 draw calls per brazier (so 56 across both). Visual identical — Points + a soft canvas alpha mask reads as smoke at the camera distance kids will see it. • The PointLight is **night-only**. During the day the brazier's additive fire sprites are bright enough to read as fire; the extra dynamic light just | J16: 400 lines, 13.4 KB. update() at L335 (46 lines). Writes 1 globals. | K16: MOD-027, MOD-098 | M16: __regenerateBraziers | N16: __sanctuaryMapType; __sanctuaryTipi1Anchor; __sanctuaryTipi1Yaw; __sanctuaryTipi2Anchor; __sanctuaryTipi2Yaw; __sanctuaryTipi3Anchor; __sanctuaryTipi3Yaw; __sanctuaryTipi4Anchor; __sanctuaryTipi4Yaw; addEventListener; removeEventListener | T16: Yes | V16: 2 | W16: 2026-05-29 feat(sanctuary): center-screen responsive welcome guide, organic shore, and mossy boulders | Y16: 400
A17: MOD-013 | B17: js/sanctuary/SanctuaryButterflies.js | C17: SUB-07 | D17: Fauna | E17: Active | F17: 21 | G17: SanctuaryButterflies | H17: FAUNA | I17: Sacred Adventures — sanctuary part 17 of N: BUTTERFLIES. Anu domain: FAUNA. **May-18 2026 rewrite:** all butterflies are YELLOW now, they live at Tipi 1 (Yellow Butterfly's tipi — hence the name), and every 5 minutes they perform a sacred ritual: • IDLE — drift in a loose cloud around Tipi 1. • SUMMON (every 5 min, first at +5 s) — every butterfly flies to a slot on a circle around YB (the seated NPC on Tipi 1's deck). A radial light bloom fades in at the centre, ramping for 1.5 s. • HOLD — the circle holds for ~6 s, bloom at full strength. • DISPERSE — bloom fades out, butterflies fan back to | J17: 436 lines, 15.5 KB. update() at L322 (98 lines). | K17: MOD-027, MOD-092, MOD-098 | N17: __sanctuaryTipi1Anchor | T17: Yes | V17: 4 | W17: 2026-05-26 feat(perf): prioritize pipeline traffic via adaptive shadow scheduling and dynamic stride sampling for lesser priorities under stress | Y17: 436
A18: MOD-014 | B18: js/sanctuary/SanctuaryCircles.js | C18: SUB-06 | D18: World environment | E18: Active | F18: 7 | G18: SanctuaryCircles | H18: ENVIRONMENT | I18: Sacred Adventures — sanctuary part 5 of 5: THE 3D CIRCLES. Three concentric circle systems that read as guiding light on the sanctuary surfaces. Anu domain: ENVIRONMENT (decorative/UX effects, not buildings). 1. Fishing-spot ring — gold double-ring on the dock end-cap, the "stand here to fish" affordance. Animated slow rotation + gentle radial pulse so the eye lands on it from any distance. 2. Pool perimeter ring — soft cyan ring just inside the water rim, tracing the pool shape. Reads as moonlight kissing the waterline; gives the pool a visible "edge of the sanctuary" feel. 3. Fish-bite rippl | J18: 303 lines, 11.0 KB. update() at L234 (48 lines). Writes 1 globals. | K18: MOD-027, MOD-098 | M18: sanctuaryPulse | N18: __sanctuaryFishingSpot; __sanctuaryWaterY | V18: 8 | W18: 2026-05-29 Revert "feat(pool): elliptical diagonal pool stretched 2x NE + blue fishing spot circle" | X18: FND-37 | Y18: 303
A19: MOD-015 | B19: js/sanctuary/SanctuaryClickToMove.js | C19: SUB-08 | D19: Player | E19: Active | F19: 9 | G19: SanctuaryClickToMove | H19: PLAYER | I19: Sacred Adventures — sanctuary part 6 of N: CLICK-TO-MOVE + KID FOOTPRINTS. Anu domain: PLAYER (the witness point — input + intent + body). What it does: • Listens for left-click on the main canvas, raycasts against the sanctuary terrain to find a (x, z) goal, and sets it as the smart-path target. • Walks the player smoothly toward the target each frame, snapping yaw so the avatar faces forward along the path. • Lays down a trail of cute kid footprints — wide chubby toes, soft short heels, slightly bigger than scale would normally suggest so they read as charming, not technical — starting a few | J19: 558 lines, 21.3 KB. update() at L412 (72 lines). Writes 4 globals. | K19: MOD-027, MOD-098 | L19: MOD-031 | M19: __sanctuaryPlayerYaw; _v4CancelClickToMove; _v4SmartWalkTo; _v4WalkTo | N19: SanctuaryMutations; __sanctuaryAvatar; __sanctuaryDockExtents; __sanctuaryDockSurface; __sanctuaryMoldTool; _v2InputSuppressed | T19: Yes | V19: 11 | W19: 2026-05-29 feat(sanctuary): center-screen responsive welcome guide, organic shore, and mossy boulders | Y19: 558
A20: MOD-016 | B20: js/sanctuary/SanctuaryControls.js | C20: SUB-12 | D20: Items & save | E20: Active | F20: 32 | G20: SanctuaryControls | H20: PLAYER | I20: Sacred Adventures — sanctuary part 8 of N: PLAYER CONTROLS UI. Bottom-of-viewport control bar for the kids who'll mold this world: ┌──────────────────────────────────────────────────────┐ │ [ 🌍 TOP-DOWN ] │ │ [ RESET ] [ SAVE ] │ └──────────────────────────────────────────────────────┘ (centred, bottom of viewport) • TOP-DOWN button — toggles top-down map view via the PIP swap (same plumbing the v2 PIP canvas uses; when swapped the main canvas shows top-down, PIP shows the chase view). • RESET button — opens a "Are you sure?" modal that, on confirm, wipes localStorage mold state + tells the Wo | J20: 373 lines, 13.8 KB. update() at L357 (0 lines). Writes 2 globals. | K20: MOD-093, MOD-098, MOD-100 | M20: __sanctuaryMoldTool; _v4ToggleTopDown | N20: SanctuaryMutations; __sanctuaryTopDownHeight; _v4ToggleJournal; _v4TogglePanel; localStorage | O20: SANCTUARY_WORLD_STATE | V20: 4 | W20: 2026-05-28 refactor(pip): remove SVG moondial iframe, render top-down PIP canvas in wrapper | Y20: 373
A21: MOD-017 | B21: js/sanctuary/SanctuaryCursor.js | C21: SUB-08 | D21: Player | E21: Active | F21: 34 | G21: SanctuaryCursor | H21: PLAYER | I21: Sacred Adventures — sanctuary part 26 of N: TOOL CURSOR. Anu domain: PLAYER (input surface). While the player is in TOP-DOWN mode AND a mold tool is armed, the OS cursor hides and a floating emoji icon follows the mouse — the kid can see at a glance which tool a click will fire (⛰ HILL / 🌲 TREE / 🌼 FLOWER / 🌿 BUSH / 🪷 LILY / 🪨 ROCK). In FPV / chase view the icon hides and the OS cursor returns. The tool palette stays as the canonical tile selector — this is just the moving feedback so the cursor isn't a confusing arrow over the map. | J21: 127 lines, 3.9 KB. update() at L100 (14 lines). Per-frame hazards: dom_write×1. | N21: __sanctuaryMoldTool; addEventListener; removeEventListener | T21: Yes | V21: 1 | W21: 2026-05-19 feat(full-session): fishing overhaul, FPS fix, dock elevation, clean world, sanctuary v2 | Y21: 127
A22: MOD-018 | B22: js/sanctuary/SanctuaryDayNight.js | C22: SUB-06 | D22: World environment | E22: Active | F22: 33 | G22: SanctuaryDayNight | H22: ENVIRONMENT | I22: Sacred Adventures — sanctuary part 24 of N: DAY ↔ NIGHT TOGGLE. Anu domain: ENVIRONMENT (sky/light is part of the ground-and- atmosphere kids' bodies must obey). Swaps the sanctuary between two lighting presets when the player clicks the new 🌙 button on the bottom controls bar: DAY — sky pale blue + warm horizon · key light golden 1.05 · hemisphere 0.65 · fog soft daylight · clear bg NIGHT — sky deep indigo + dusk horizon · key light cool 0.42 · hemisphere 0.22 with cool ground · fog twilight · low bg Transitions over ~1.4 s so the change reads as a slow breath, not a snap. While in the wash a | J22: 181 lines, 6.0 KB. update() at L157 (11 lines). | K22: MOD-093, MOD-098, MOD-100 | O22: SEASON_CHANGE | V22: 2 | W22: 2026-05-26 feat(pip): add branches back to pip and bump sw cache to v24 | Y22: 181
A23: MOD-019 | B23: js/sanctuary/SanctuaryDock.js | C23: SUB-06 | D23: World environment | E23: Active | F23: 5 | G23: SanctuaryDock | H23: STRUCTURES | I23: Sacred Adventures — sanctuary part 3 of 5: THE FISH DOCK. Anu domain: STRUCTURES. Per her sentience note: "Built world — homes, doors, sockets, village objects." The dock is the player's threshold into the pool — they walk out onto the planks, the camera follows, the fishing spot is at the dock's far end. Geometry (all procedural, ~500 tris): shore_anchor pool_centre ─────────────┬─────────[planks]──────────────┬──● fishing spot │ │ · 2 stair steps to walk up · raised platform tip • 8 planks running pool-ward (BoxGeometry, butted side-by-side). • 4 support posts (CylinderGeometry, dipped into | J23: 504 lines, 21.4 KB. update() at L483 (2 lines). Writes 4 globals. | K23: MOD-027, MOD-098 | M23: __regenerateDock; __sanctuaryDockExtents; __sanctuaryDockSurface; __sanctuaryFishingSpot | N23: __sanctuaryMapType | V23: 13 | W23: 2026-06-01 feat(dock): photoreal procedural wood grain + bump on planks, rails, and support logs | X23: FND-38 | Y23: 504
A24: MOD-020 | B24: js/sanctuary/SanctuaryDragonfly.js | C24: SUB-07 | D24: Fauna | E24: Active | F24: 41 | G24: SanctuaryDragonfly | I24: Sacred Adventures — sanctuary: Dragonfly. One small photo-real dragonfly that zips across the pond at random intervals. Per user spec (May-25 2026): "small dragon fly zips by in photo realistic style" Implementation: • Single THREE.Sprite using a procedural CanvasTexture so we don't fetch any asset. Body + wings + jewel-tone iridescence drawn once into a 256×256 canvas; sprite always faces the camera. • Flight path = a Bezier-ish arc across the pond at random start / end points, height 0.6-1.6 m above water. Each "zip" lasts 2-4 s. • Idle gap between zips: 12-30 s (this is ambient flavor, not | J24: 301 lines, 9.7 KB. update() at L240 (44 lines). Writes 1 globals. | K24: MOD-027, MOD-092, MOD-098 | M24: __sanctuaryDragonflies | V24: 4 | W24: 2026-05-26 feat(perf): prioritize pipeline traffic via adaptive shadow scheduling and dynamic stride sampling for lesser priorities under stress | Y24: 301
A25: MOD-021 | B25: js/sanctuary/SanctuaryFish.js | C25: SUB-07 | D25: Fauna | E25: Active | F25: 6 | G25: SanctuaryFish | I25: Sacred Adventures — sanctuary part 4 of 5: THE FISH. Loads `Assets/Fish/fish.obj` (same trout mesh as v2 Pool2), bakes the 3DS Max Z-up export upright, and swims with velocity-based orbital physics: head leads the path, body wiggles on yaw, gentle depth bob. | J25: 1730 lines, 70.7 KB. update() at L699 (898 lines). Per-frame hazards: traverse×2, alloc_three×7, dom_write×1. Writes 5 globals. | K25: MOD-027, MOD-092, MOD-098 | M25: __sanctuaryFishCount; __sanctuaryFishSchool; __sanctuaryFishTemplate; __sanctuaryFrogOnLily; __sanctuarySpawnBabyFish | N25: AudioContext; __interestedFish; __sanctuaryAvatar; __sanctuaryBobberPos; __sanctuaryDragonflies; __sanctuaryFishingSpawnRipple; __sanctuaryFrogs; __sanctuaryWaterY; anuOrchestrator; sanctuaryPulse; showWoWCombatText; webkitAudioContext | V25: 17 | W25: 2026-05-29 feat(sanctuary): overhaul sacred pool depth, schooling small fish, funny real-fish eat-jumps, and freeze PIP animations | X25: FND-15, FND-33, FND-34, FND-42 | Y25: 1730
A26: MOD-022 | B26: js/sanctuary/SanctuaryFishJumps.js | C26: SUB-07 | D26: Fauna | E26: Active | F26: 31 | G26: SanctuaryFishJumps | H26: FAUNA | I26: Sacred Adventures — sanctuary part 23 of N: FISH JUMPS. Anu domain: FAUNA. Magical surprise life. Every 8–18 seconds Anu picks one fish from `window.__sanctuaryFishSchool` (published by SanctuaryFish), launches a small fish-shaped silhouette on a parabolic arc breaking the water surface, and fires `window.sanctuaryPulse(x, z)` so a ripple expands from the entry point. Cosmetic only — the rendered school below the water keeps swimming on its lazy orbital paths. Per-jump cost: one Mesh added/removed (~16 tris). Active jumps cap at 1 simultaneous — staggers stay clean. | J26: 197 lines, 6.5 KB. update() at L179 (4 lines). | K26: MOD-027, MOD-098 | N26: __sanctuaryFishSchool; __sanctuaryFishTemplate; __sanctuaryWaterY; sanctuaryPulse | V26: 4 | W26: 2026-05-29 feat(sanctuary): center-screen responsive welcome guide, organic shore, and mossy boulders | Y26: 197
A27: MOD-023 | B27: js/sanctuary/SanctuaryFishing.js | C27: SUB-11 | D27: Fishing | E27: Active | F27: 38 | G27: SanctuaryFishing | I27: Sacred Adventures — sanctuary part 34: FISHING MINI-GAME (v2). Changes from v1: • Lure always casts to pool centre. • Rod rotates to aim at pool centre, pitch scales with distance. • Camera: 10 ft (3.048 m) above water, 4 ft (1.219 m) behind avatar, locked onto pool centre the whole time. • Real J-hook (shank + half-torus curve + barb point) under bobber. • Water ripple rings expand from lure position every 0.6–2.2 s. • Turn-based bite system: 6-second turns, 1–3 % per turn, +5 % surge every 1–3 turns (chosen randomly at cast time). | J27: 2997 lines, 122.2 KB. update() at L1641 (981 lines). Per-frame hazards: traverse×3, alloc_three×2, matrix_update×4. Writes 11 globals. | K27: MOD-027, MOD-098, MOD-099, MOD-103 | M27: __interestedFish; __sanctuaryBobberPos; __sanctuaryFishCount; __sanctuaryFishingActive; __sanctuaryFishingSpawnRipple; __sanctuaryHasFishCaught; __sanctuaryPlayerYaw; _v2InputSuppressed; _v4InputSuppressed; _v4StartFishing; sanctuaryFishingFocus | N27: AnuUniverse; AudioContext; __sanctuaryAvatar; __sanctuaryDockRoot; __sanctuaryFishSchool; __sanctuaryFishTemplate; __sanctuaryFishingSpot; __sanctuaryKeyboardLook; __sanctuarySpawnBabyFish; _v4CancelClickToMove; addEventListener; anuOrchestrator; removeEventListener; sanctuaryGrant; sanctuaryPulse; webkitAudioContext | V27: 40 | W27: 2026-10-22 perf(pip,fishing): drop limbo PIP_FRAME relay, skip dead fishing scan, no transmission pass | X27: FND-18, FND-28, FND-30, FND-32, FND-41 | Y27: 2997
A28: MOD-024 | B28: js/sanctuary/SanctuaryFlora.js | C28: SUB-16 | D28: Legacy / unused code | E28: Unreferenced by any entry page | G28: SanctuaryFlora | I28: Sacred Adventures — sanctuary part 12 of N: BASELINE FLORA. Pass-B rewrite (May-18 2026): the prior implementation spawned ~300 Group/Mesh nodes for 50 flower clusters + 12 mushroom clusters + 40 grass tufts. Anu flagged `draw-calls SEVERE` (355 total) the moment this module activated. The new implementation uses `InstancedMesh` for every population: • Stems — 1 InstancedMesh (all wildflower stems share a single dark-green stem material). • Blossoms — 5 InstancedMesh (one per palette colour). Each gets ~10 instances on a 50-cluster scatter. • Mushroom stems — 1 InstancedMesh (cream). • Mushroo | J28: 571 lines, 19.1 KB. update() at L528 (3 lines). Writes 1 globals. | K28: MOD-027, MOD-098 | M28: __sanctuaryFloraTimeUniform | V28: 3 | W28: 2026-05-29 feat(sanctuary): overhaul sacred pool depth, schooling small fish, funny real-fish eat-jumps, and freeze PIP animations | Y28: 571
A29: MOD-025 | B29: js/sanctuary/SanctuaryFpsHud.js | C29: SUB-16 | D29: Legacy / unused code | E29: Unreferenced by any entry page | G29: SanctuaryFpsHud | I29: Sacred Adventures — sanctuary part 33 of N: tree-toggle CTA. Originally hosted the standalone #v4-fps-hud pill alongside the tree-toggle button. The pill read from `getFrameBudgetSnapshot()` (render-call cost) while OrchestratorHud's #v2-fps read from `orc.smoothFPS` (actual frame rate) — same word "FPS", different sensors, divergent readings (e.g. headless: 333 vs 30). To stop the confusion, the pill was retired and OrchestratorHud is now the single source of truth for on-screen FPS. What remains here: the top-middle glassmorphic "🌲 TREES …" toggle button. The module name (SanctuaryFpsHud) is | J29: 104 lines, 4.0 KB. No update(). Writes 1 globals. | M29: __sanctuaryTreesHidden | V29: 9 | W29: 2026-05-27 fix(hud,anu): unify FPS source on orc.smoothFPS + make .report() return real snapshots | Y29: 104
A30: MOD-026 | B30: js/sanctuary/SanctuaryFrogs.js | C30: SUB-07 | D30: Fauna | E30: Active | F30: 43 | G30: SanctuaryFrogs | H30: FAUNA | I30: Sacred Adventures — sanctuary: SanctuaryFrogs Procedural implementation of frogs and lily pads with AI state machines. Elements: 1. Lily Pads & Flowers: Flat cylinders with v-notches + procedural petal clusters. 2. Frogs: Procedural geometry (green body, white belly, eyes, black smile). AI States: - SWIM: Moving in water, only eyes/top visible. - BASK_LILY: Resting on a lily pad. - BASK_SHORE: Resting on the shore. - FLEE: Jumps from shore to water/lily when player approaches. - JUMP: Parabolic motion between two points. Anu domain: FAUNA + FLORA | J30: 1120 lines, 41.5 KB. update() at L645 (281 lines). Writes 3 globals. | K30: MOD-027, MOD-092 | M30: __sanctuaryFrogOnLily; __sanctuaryFrogs; __sanctuaryFrogsRegenerate | N30: WorldPlayer; __sanctuaryBobberPos; __sanctuaryDragonflies; __sanctuaryFishSchool; __sanctuaryLilyPads; sanctuaryPulse | V30: 10 | W30: 2026-06-02 feat(pool): clearer water reveals the deep basin + 10 bigger frogs | Y30: 1120
A31: MOD-027 | B31: js/sanctuary/SanctuaryGround.js | C31: SUB-06 | D31: World environment | E31: Active | F31: 3 | G31: SanctuaryGround | H31: ENVIRONMENT | I31: Sacred Adventures — sanctuary part 1 of 5: GROUND + ATMOSPHERE. Anu domain: ENVIRONMENT. Per her sentience note: "The ground and atmosphere that all bodies must obey." This module owns: • Terrain — gentle organic clearing that cradles the pool. Single PlaneGeometry with vertex displacement; the pool basin is carved at module load via shared `sanctuaryGroundY(x, z)` so other parts (pool, dock, fish, circles) all sit on the same heightfield. • Sky — soft warm-to-cool gradient hemisphere following the camera. No moving clouds, no fbm — the sanctuary should read STILL. • Light — hemisphere + key d | J31: 833 lines, 31.3 KB. update() at L801 (5 lines). | K31: MOD-036, MOD-098 | L31: MOD-003, MOD-004, MOD-005, MOD-006, MOD-007, MOD-008, MOD-009, MOD-011, MOD-012, MOD-013, MOD-014, MOD-015, MOD-019, MOD-020, MOD-021, MOD-022, MOD-023, MOD-024, MOD-026, MOD-028, MOD-031, MOD-034, MOD-035, MOD-039, MOD-042, MOD-043, MOD-047 | N31: __sanctuaryDockSurface; __sanctuaryWaterY | S31: Assets/landscape-scenes/terrain/grass-seamless.png | V31: 16 | W31: 2026-05-30 feat(sanctuary): strong pronounced neumorphic hex tiles for village-view planning | Y31: 833
A32: MOD-028 | B32: js/sanctuary/SanctuaryHexGrid.js | C32: SUB-06 | D32: World environment | E32: Registered, activation commented out | G32: SanctuaryHexGrid | H32: ENVIRONMENT | I32: Sacred Adventures — sanctuary: LEGACY GOLD HEX-LINE GRID. Ports the warm-gold neumorphic hexagon OUTLINE grid from the legacy engine (`EnvironmentBuilder.createVillageHexGrid`) onto the v2 sanctuary scene. The legacy `EnvironmentBuilder` is not loaded by the sanctuary boot path, so this is a self-contained re-implementation of just the line ring — no filled hex tiles, only the elegant boardgame outlines the user asked to bring back. Legacy fidelity (1:1 with EnvironmentBuilder lines 184-224): • 25 m hexagons (RADIUS 25, GAP 0.5 → size 24.5) • 0.25 m border width (inner hole at size - 0.25) • t | J32: 153 lines, 5.4 KB. update() at L139 (0 lines). | K32: MOD-027, MOD-098 | V32: 1 | W32: 2026-05-29 feat(fishing): soften rod struggle sways, and integrate Claude's gold hex grid overlay module | Y32: 153
A33: MOD-029 | B33: js/sanctuary/SanctuaryInventory.js | C33: SUB-12 | D33: Items & save | E33: Active | F33: 36 | G33: SanctuaryInventory | H33: ITEMS | I33: Sacred Adventures — sanctuary part 28 of N: HARVEST INVENTORY. Anu domain: ITEMS (Anu's `items` domain finally has something in it!). The `harvest` verb in Anu's vocabulary becomes real. When a kid clicks (in FPV/chase view) on anything tagged with `anuInteractionVerbs` including HARVEST — bushes, mushroom clusters, planted flowers, planted trees, fish — the world spawns an inventory item of a matching kind into a small floating bag UI in the corner. Five item kinds exposed: 🌿 leaf (from bushes) 🍓 berry (from bushes that rolled the berry payload) 🍄 mushroom (from mushroom clusters) 🌼 petal (fr | J33: 238 lines, 8.7 KB. update() at L216 (0 lines). Writes 2 globals. | K33: MOD-093, MOD-098, MOD-100 | M33: sanctuaryGrant; sanctuaryInventory | O33: ITEM_EVENT | T33: Yes | V33: 1 | W33: 2026-05-19 feat(full-session): fishing overhaul, FPS fix, dock elevation, clean world, sanctuary v2 | Y33: 238
A34: MOD-030 | B34: js/sanctuary/SanctuaryJournalBridge.js | C34: SUB-13 | D34: UI shell & journal | E34: Active | F34: 40 | G34: SanctuaryJournalBridge | I34: Sacred Adventures — sanctuary: Journal ↔ Anu bridge. The SacredGame.Journal.html iframe communicates exclusively via postMessage (self-contained, no Panel dependencies). This module sits in the parent window, translates those messages into Anu's InteractionBus events, AND replies to journal-side queries with fresh sensorium / governance snapshots. Why a dedicated bridge module: • Anu wants to KNOW about UI state changes — journal open/close is a player-mode signal Anu reads in its sensorium roll-up. • The journal wants to DISPLAY live world state — entity counts, governance check pass-rate, ac | J34: 172 lines, 6.7 KB. No update(). Writes 1 globals. | K34: MOD-093, MOD-098 | M34: sanctuaryJournalBridge | N34: AnuUniverse; addEventListener; anuOrchestrator; clearInterval; removeEventListener; setInterval | T34: Yes | V34: 1 | W34: 2026-05-25 feat+perf: journal↔Anu bridge + Help button + Welcome Prev + de-spring + kill 20+ backdrop-filters | Y34: 172
A35: MOD-031 | B35: js/sanctuary/SanctuaryKeyboardLook.js | C35: SUB-08 | D35: Player | E35: Active | F35: 24 | G35: SanctuaryKeyboardLook | H35: PLAYER | I35: Sacred Adventures — sanctuary part 18 of N: KEYBOARD MOVE + LOOK. Anu domain: PLAYER (input + intent). The click-to-move module already walks the body to a goal point; this module adds WASD direct steering + arrow-key look-around so the player can do what they want every frame instead of one click at a time. Binding (kid-friendly, no caps required, no modifiers): W / ↑ move forward (toward where the camera is looking, on the XZ plane) S / ↓ move backward A strafe left D strafe right Q turn yaw left (also rebinds to bumper-thumb friendly) E turn yaw right ← → turn yaw left / right (arrow altern | J35: 294 lines, 11.9 KB. update() at L112 (170 lines). Per-frame hazards: alloc_three×2, dom_query×1. Writes 1 globals. | K35: MOD-015, MOD-027 | M35: __sanctuaryPlayerYaw | N35: __sanctuaryAvatar; __sanctuaryJoystickInput; __sanctuaryZoomFactor; _v4CancelClickToMove; _v4InputSuppressed; addEventListener; removeEventListener | T35: Yes | V35: 7 | W35: 2026-05-28 fix(fishing,avatar,travel): gauge stays in PIP at low opacity + half-submerged swim + 40mm decal clearance | Y35: 294
A36: MOD-032 | B36: js/sanctuary/SanctuaryMapGeneratorUi.js | C36: SUB-10 | D36: Structures & village building | E36: Active | F36: 23 | G36: SanctuaryMapGeneratorUi | I36: Sacred Adventures — SanctuaryMapGeneratorUi The GENERATE SCENE / CLEAR SCENE buttons have been merged into SanctuaryToolPalette, which now renders a unified "FLORA & BUILD" panel attached flush below the OrchestratorHud in Village View. This module stub is kept so the index.html boot sequence doesn't break. | J36: 17 lines, 0.5 KB. update() at L14 (0 lines). | T36: Yes | V36: 3 | W36: 2026-05-26 refactor: promote index.v4.html → index.html as canonical entry point | Y36: 17
A37: MOD-033 | B37: js/sanctuary/SanctuaryMutations.js | C37: SUB-10 | D37: Structures & village building | E37: Active | F37: 13 | G37: SanctuaryMutations | H37: ENVIRONMENT | I37: Sacred Adventures — sanctuary part 9 of N: WORLD-MUTATION REGISTRY. The foundation kids stand on when they shape this world. Each recognised "tool" (grow_hill, plant_tree, plant_bush, plant_lily, plant_rock) becomes a registered mutation type. When the player acts in top-down mode, the active tool publishes one mutation through this registry; the registry then: 1. Applies the visual effect (spawns mesh / lifts terrain / etc.). 2. Records the mutation in a list so SAVE serialises it. 3. Dispatches `ANU_EVENTS.SANCTUARY_MOLD` on the InteractionBus so Anu sees every kid edit. This module is the S | J37: 169 lines, 5.2 KB. update() at L157 (0 lines). Writes 1 globals. | K37: MOD-093, MOD-098, MOD-100 | M37: SanctuaryMutations | N37: localStorage | O37: SANCTUARY_MOLD | T37: Yes | V37: 1 | W37: 2026-05-19 feat(full-session): fishing overhaul, FPS fix, dock elevation, clean world, sanctuary v2 | Y37: 169
A38: MOD-034 | B38: js/sanctuary/SanctuaryPondTrees.js | C38: SUB-06 | D38: World environment | E38: Active | F38: 42 | G38: SanctuaryPondTrees | H38: FLORA | I38: Sacred Adventures — sanctuary: SanctuaryPondTrees (InstancedMesh refactor) Recreates the misty sacred pond atmosphere using high-quality photorealistic assets (tree.glb, bush.glb, and reeds.glb). All flora is now rendered using THREE.InstancedMesh to achieve massive density (36 trees, 72 bushes, 24 reeds) with exactly zero FPS drop. Anu domain: FLORA | J38: 354 lines, 14.1 KB. update() at L335 (8 lines). | K38: MOD-027, MOD-104 | S38: Assets/bush.glb; Assets/flora/reeds.glb; Assets/tree.glb | V38: 7 | W38: 2026-05-30 perf(scene): cull far flora + raise PIP stride + tree frustum-cull/leaf-shadow | X38: FND-43 | Y38: 354
